Workbook

Sheet 01_작성안내
A1: 커머스 본부 주간 일간업무일지 (업무 통합 · 중복 진단용)
A3: ■ 작성 목적
B4: 현재 커머스 본부는 [미디어커머스 / 브랜드커머스 / 해외제조] 3개 조직으로 분리 운영 중입니다.
B5: 3개 조직이 실제로 어떤 업무를 얼마나 하고 있는지 시간대별로 기록하여,
B6: ① 팀 간 중복 수행 업무를 찾아내고 ② 통합 대상 업무와 단일 창구를 설계하는 것이 목적입니다.
B7: ※ 개인 성과평가 목적이 아닙니다. 있는 그대로 솔직하게 기록해야 통합 설계가 정확해집니다.
A9: ■ 작성 대상 / 기간
B10: 대상: 커머스 본부 3개 팀 전 구성원 (팀장 포함)
B11: 기간: 1주일(월~금) / 매일 퇴근 전 당일분 작성 권장 (몰아쓰면 정확도가 급격히 떨어집니다)
A13: ■ 시트 구성 및 사용 순서
B14: ① 02_업무일지양식 → 개인이 작성. 30분 단위 시간대가 미리 채워져 있습니다. 사본을 만들어 1인 1개 사용.
B15: ② 03_통합데이터 → 취합 담당자가 전원의 작성분을 이 시트에 '값 붙여넣기'로 모읍니다.
B16: ③ 04_중복업무분석 → 자동 계산. 어떤 업무를 몇 개 팀이 중복 수행하는지 자동으로 나옵니다.
B17: ④ 05_통합기회도출 → 분석 결과를 보고 통합 방안을 수기로 정리합니다.
B18: ⑤ 06_분류코드 → 드롭다운 원본. 우리 조직에 없는 업무는 지우고, 빠진 업무는 추가하세요.
A20: ■ 작성 6원칙 (이대로 써야 분석이 됩니다)
B21: 1) 30분 단위로 빠짐없이 채운다. 비는 시간이 없도록 하되, 한 슬롯에 여러 업무가 섞이면 대표 업무 1개를 적는다.
B22: 2) 업무 중분류는 반드시 드롭다운에서 고른다. 자유 입력하면 중복 집계가 되지 않는다.
B23: 3) '업무내용'은 동사로 구체적으로. (X) 광고 관리 → (O) A브랜드 메타 광고 소재 3개 교체 및 예산 재배분
B24: 4) '협업 대상'을 반드시 적는다. 같은 거래처·같은 MD·같은 대행사를 여러 팀이 각자 접촉하는 것이 대표적 중복이다.
B25: 5) '사용 시스템·툴'을 적는다. 같은 일을 서로 다른 툴로 하는 것도 통합 대상이다.
B26: 6) '타팀 중복예상' 칸에 본인의 감(感)을 남긴다. 데이터로 안 잡히는 중복을 잡아내는 단서가 된다.
A28: ■ 분석 결과 읽는 법 (04 시트)
B29: · 수행팀수 3 → 3개 팀이 모두 하는 업무. 통합 1순위 (단일 창구화 또는 전담 배치)
B30: · 수행팀수 2 → 2개 팀 중복. 통합 2순위 (역할 경계 재정의)
B31: · 통합우선순위점수 = 수행팀수 × 총 소요시간(h). 점수가 높을수록 통합 효과가 큼
B32: · 같은 중분류라도 '협업 대상'과 '대상 브랜드'가 다르면 실제로는 중복이 아닐 수 있으므로 05 시트에서 반드시 검증
A34: ■ 전제 / 가정
B35: · 기본 근무시간을 09:00~18:00, 30분 단위로 가정했습니다. 조직 운영시간이 다르면 02 시트의 시간 열을 수정하세요.
B36: · 일자는 02 시트 B3 셀(기준 주 월요일)을 입력하면 자동 계산됩니다.
B37: · 노란색 셀 = 직접 입력, 흰색 셀 = 드롭다운 선택, 회색 셀 = 수식(수정 금지)

Sheet 06_분류코드
A1: 업무 분류 코드 마스터 (드롭다운 원본 - 수정 시 전 시트에 반영됨)
A3: 업무 대분류 | B3: 업무 중분류 (코드) | D3: 소속팀 | F3: 반복주기 | H3: 업무 성격 | J3: 타팀 중복 예상 | L3: 대분류 목록
A4: 상품기획·소싱 | B4: PLN-01 신상품 아이템 발굴/시장조사 | D4: 미디어커머스 | F4: 매일 | H4: 정형(매뉴얼화 가능) | J4: 예 - 확실히 중복 | L4: 상품기획·소싱
A5: 상품기획·소싱 | B5: PLN-02 경쟁사·트렌드 분석 | D5: 브랜드커머스 | F5: 주 2~3회 | H5: 반정형 | J5: 아마도 중복 | L5: 제조·생산관리
A6: 상품기획·소싱 | B6: PLN-03 원가·판가(마진) 설계 | D6: 해외제조 | F6: 주 1회 | H6: 비정형(판단 필요) | J6: 아니오 - 우리팀 고유 | L6: 마케팅·광고운영
A7: 상품기획·소싱 | B7: PLN-04 공급처(벤더) 발굴·컨택 | F7: 격주 | J7: 모름 | L7: 콘텐츠제작
A8: 상품기획·소싱 | B8: PLN-05 샘플 요청·검토 | F8: 월 1회 | L8: 채널·스토어운영
A9: 상품기획·소싱 | B9: PLN-06 상품 스펙·사양 확정 | F9: 분기/비정기 | L9: CS·물류·재고
A10: 제조·생산관리 | B10: MFG-01 해외공장/거래처 커뮤니케이션 | F10: 1회성 | L10: 데이터·정산
A11: 제조·생산관리 | B11: MFG-02 발주(PO) 작성·전송 | L11: 기획·보고·회의
A12: 제조·생산관리 | B12: MFG-03 생산일정 관리·납기 독촉 | L12: 사내시스템·자동화
A13: 제조·생산관리 | B13: MFG-04 품질검사(QC)·불량 대응 | L13: 파트너·대리점관리
A14: 제조·생산관리 | B14: MFG-05 수입통관·인증(KC 등) 처리 | L14: 기타·행정
A15: 제조·생산관리 | B15: MFG-06 선적·입고 일정 관리
A16: 제조·생산관리 | B16: MFG-07 단가 협상·계약
A17: 제조·생산관리 | B17: MFG-08 MSDS·라벨 등 제품 표시사항 제작
A18: 마케팅·광고운영 | B18: MKT-01 광고 계정 세팅·집행(메타/구글 등)
A19: 마케팅·광고운영 | B19: MKT-02 광고 성과 모니터링·최적화
A20: 마케팅·광고운영 | B20: MKT-03 광고 소재 기획·시안 검토
A21: 마케팅·광고운영 | B21: MKT-04 인플루언서·체험단 섭외/관리
A22: 마케팅·광고운영 | B22: MKT-05 프로모션·기획전 기획
A23: 마케팅·광고운영 | B23: MKT-06 CRM(문자/알림톡/메일) 발송
A24: 마케팅·광고운영 | B24: MKT-07 대행사 커뮤니케이션·관리
A25: 마케팅·광고운영 | B25: MKT-08 제휴마케팅(링크프라이스 등) 운영·성과확인
A26: 콘텐츠제작 | B26: CNT-01 상세페이지 기획·제작
... A64: 기타·행정 | B64: ETC-05 휴게·점심
A66: ■ 신규 추가 분류코드 — 2026-08-10~14 김송희(브랜드커머스) 업무일지 반영분
A67: 업무 대분류 | B67: 업무 중분류 (신규 코드) | D67: 추가 사유
A68: 제조·생산관리 | B68: MFG-08 MSDS·라벨 등 제품 표시사항 제작 | D68: MSDS·라벨 등 제품 표시사항 제작 업무가 기존 MFG-05(수입통관·인증)로 포괄되지 않아 신설
A69: 마케팅·광고운영 | B69: MKT-08 제휴마케팅(링크프라이스 등) 운영·성과확인 | D69: 링크프라이스 등 제휴(CPS) 채널 운영·주간보고가 MKT-01/02(직접 광고 집행)와 성격이 달라 신설
A70: 콘텐츠제작 | B70: CNT-07 카탈로그·영업자료 제작 | D70: 부자재 소개 카달로그 등 오프라인·영업용 자료 제작이 CNT-01(상세페이지)과 달라 신설
A71: CS·물류·재고 | B71: OPS-06 일일 주문,매출 확인 | D71: 매일 반복되는 주문건 확인 업무가 기존 OPS-01~05에 없어 신설
A72: 기획·보고·회의 | B72: MGT-06 팀원 업무·산출물 검토·피드백 | D72: 리드 직무의 핵심인 팀원 산출물 검토·피드백·컨펌이 MGT-01~05에 없어 신설
A73: 기획·보고·회의 | B73: MGT-07 업무 인수인계·이관 | D73: 조직 개편에 따른 업무 인수인계(그로홈 등)를 기록할 코드가 없어 신설
A74: 사내시스템·자동화 ★신규 대분류 | B74: SYS-01 사내 시스템·앱 기획/개선 요청 | D74: 소싱앱·CRM센터 등 사내 시스템 기획/개선 요청 업무를 담을 대분류·코드가 없어 신설
A75: 파트너·대리점관리 ★신규 대분류 | B75: PTR-01 대리점·파트너사 방문·미팅 | D75: 대리점·파트너사 대상 방문/미팅 업무를 담을 대분류·코드가 없어 신설
A76: 파트너·대리점관리 ★신규 대분류 | B76: PTR-02 대리점·파트너 인터뷰·VOC 수집 | D76: 대리점 인터뷰·VOC 수집(질문지 제작·현장 인터뷰)을 담을 코드가 없어 신설

Sheet 02_업무일지양식
A1: 커머스 본부 일간업무일지 (주간) — 30분 단위 기록
A2: 소속팀 | B2: 브랜드커머스 | C2: 이름 | D2: 김송희 | F2: 직위/직무 | G2: 브랜드커머스, 모여라딜 리드
A3: 기준 주(월요일) | B3: 46244 | C3: 작성일 | D3: 46248 | F3: 팀장 확인
A4: 작성법 ▶ B3(월요일 날짜)만 입력하면 일자가 자동 계산됩니다. 6~7열은 반드시 드롭다운에서 선택하세요(자유입력 시 중복분석 불가). 빈 시간대가 없도록 채우고, 야근·조기출근은 각 요일 하단 [추가] 행에 시간을 직접 입력하세요. 7행은 작성 예시입니다(작성 시 삭제).
A5: ※ 작성 근거 ▶ 본 시트는 POUR OS 주간 업무보드(2026-08-10~14, 김송희) 기록을 기준으로 작성했습니다. 보드에 항목으로 잡히지 않는 ETC-01(메일·메신저 확인)·ETC-05(휴게·점심), 그리고 각 업무의 시작/종료 시각과 소요시간은 09:00~18:00 근무 기준 추정치이므로 본인 확인 후 조정해 주세요. 여러 날 이어진 진행중 업무 2건(DAT-04 단가·공헌이익 대시보드 / MFG-08 코트재 MSDS 31종)은 본인 확인에 따라 화·수·목에만 배분했습니다(월요일은 타 업무 11건으로 포화, 금요일은 부산 외근).
A6: 일자 | B6: 요일 | C6: 시작 | D6: 종료 | E6: 소요 (분) | F6: 업무 대분류 | G6: 업무 중분류 (드롭다운 필수) | H6: 업무 내용 (구체적으로) | I6: 대상 브랜드/상품/채널 | J6: 사용 시스템·툴 | K6: 사용 시스템·툴 링크 | L6: 협업 대상 (사내) | M6: 협업 대상 (사외/거래처) | N6: 산출물 | O6: 반복주기 | P6: 업무 성격 | Q6: 타팀 중복예상 | R6: 개선·자동화 아이디어
A7: =IF($B$3="","",$B$3+0) | B7: 월 | C7: 0.375 | D7: 0.39583333 | E7: =IF(OR(C7="",D7=""),"",(D7-C7)*1440) | F7: 기타·행정 | G7: ETC-01 메일·메신저 확인 및 회신 | H7: 출근 후 메일·메신저·업무보드 확인 및 회신 | I7: 전사 | J7: CRM센터-POUR OS(업무보드) | K7: https://pourstorecrm.web.app/pour-os | N7: 회신 처리 | O7: 매일 | P7: 정형(매뉴얼화 가능) | Q7: 예 - 확실히 중복 | R7: 팀별 요청·공지를 업무보드 알림 하나로 일원화
A8: =IF($B$3="","",$B$3+0) | B8: 월 | C8: 0.39583333 | D8: 0.41666667 | E8: =IF(OR(C8="",D8=""),"",(D8-C8)*1440) | F8: 데이터·정산 | G8: OPS-06 일일 주문,매출 확인 | H8: 금일 주문,매출 확인 | I8: POUR스토어 / 자사몰·오픈마켓 | J8: 사방넷 | N8: 일일 주문 확인 내역 | O8: 매일 | P8: 정형(매뉴얼화 가능) | Q8: 예 - 확실히 중복 | R8: 채널별 주문을 통합 주문판으로 자동 취합
A9: =IF($B$3="","",$B$3+0) | B9: 월 | C9: 0.41666667 | D9: 0.45833333 | E9: =IF(OR(C9="",D9=""),"",(D9-C9)*1440) | F9: 마케팅·광고운영 | G9: MKT-08 제휴마케팅(링크프라이스 등) 운영·성과확인 | H9: 링크프라이스 제휴광고 집행 현황 확인 및 신제품 검색 시 상위노출 여부 점검 | I9: POUR스토어 / 링크프라이스·네이버쇼핑 | J9: 링크프라이스 관리자, 네이버쇼핑 | M9: 링크프라이스 | N9: 제휴광고 현황 점검 메모 | O9: 주 1회 | P9: 반정형 | Q9: 아마도 중복 | R9: 제휴·검색광고 성과를 본부 공용 대시보드로 자동 수집
A10: =IF($B$3="","",$B$3+0) | B10: 월 | C10: 0.45833333 | D10: 0.47916667 | E10: =IF(OR(C10="",D10=""),"",(D10-C10)*1440) | F10: 마케팅·광고운영 | G10: MKT-05 프로모션·기획전 기획 | H10: 8월 프로모션 기획 요청 — 민지님께 기획 방향 전달 및 작성 요청 | I10: POUR스토어 | J10: CRM센터-POUR OS(업무보드) | K10: https://pourstorecrm.web.app/pour-os | L10: 김민지 | N10: 프로모션 기획 요청서 | O10: 월 1회 | P10: 반정형 | Q10: 아마도 중복 | R10: 프로모션 기획 요청 양식 표준화 + 본부 공용 프로모션 캘린더
A11: =IF($B$3="","",$B$3+0) | B11: 월 | C11: 0.47916667 | D11: 0.5 | E11: =IF(OR(C11="",D11=""),"",(D11-C11)*1440) | F11: 파트너·대리점관리 | G11: PTR-02 대리점·파트너 인터뷰·VOC 수집 | H11: 금요일 부산 대리점 방문 미팅·인터뷰 질문지 제작 요청(란님께) | I11: 대리점(가나랜드·경남지사) | J11: CRM센터-POUR OS(업무보드) | K11: https://pourstorecrm.web.app/pour-os | L11: 이란 | N11: 대리점 인터뷰 질문지 | O11: 분기/비정기 | P11: 반정형 | Q11: 모름 | R11: 대리점 인터뷰 질문지 표준 템플릿화
A12: =IF($B$3="","",$B$3+0) | B12: 월 | C12: 0.5 | D12: 0.54166667 | E12: =IF(OR(C12="",D12=""),"",(D12-C12)*1440) | F12: 기타·행정 | G12: ETC-05 휴게·점심 | H12: 점심 및 휴게 | O12: 매일 | P12: 정형(매뉴얼화 가능) | Q12: 예 - 확실히 중복
A13: =IF($B$3="","",$B$3+0) | B13: 월 | C13: 0.54166667 | D13: 0.5625 | E13: =IF(OR(C13="",D13=""),"",(D13-C13)*1440) | F13: 사내시스템·자동화 | G13: SYS-01 사내 시스템·앱 기획/개선 요청 | H13: CRM센터 NPS 기능 개선 요청 — 채림님께 개선 항목 정리·전달 | I13: CRM센터 | J13: CRM센터 | K13: https://pourstorecrm.web.app/pour-os | L13: 양채림 | N13: 기능 개선 요청 내역 | O13: 주 1회 | P13: 반정형 | Q13: 모름 | R13: 사내 시스템 개선 요청을 티켓(이슈보드)으로 단일 창구화
A14: =IF($B$3="","",$B$3+0) | B14: 월 | C14: 0.5625 | D14: 0.58333333 | E14: =IF(OR(C14="",D14=""),"",(D14-C14)*1440) | F14: 사내시스템·자동화 | G14: SYS-01 사내 시스템·앱 기획/개선 요청 | H14: 소싱앱 기능 고도화 요청-운전하면서도 쉽고빠르게 사용가능하게(정하님께) | I14: 소싱앱 | J14: 소싱앱 | K14: 소싱 관리 · 모여라딜 (moyeoradeal-sourcing.pages.dev) | L14: 용정하 | N14: 기능 고도화 요청 내역 | O14: 주 1회 | P14: 반정형 | Q14: 모름 | R14: 사내 시스템 개선 요청을 티켓(이슈보드)으로 단일 창구화
A15: =IF($B$3="","",$B$3+0) | B15: 월 | C15: 0.58333333 | D15: 0.625 | E15: =IF(OR(C15="",D15=""),"",(D15-C15)*1440) | F15: 사내시스템·자동화 | G15: SYS-01 사내 시스템·앱 기획/개선 요청 | H15: 소싱앱 UX/UI 개선 — 정하님 추가 고도화 건 화면별 피드백 작성 | I15: 소싱앱 | J15: 소싱앱 | K15: 소싱 관리 · 모여라딜 (moyeoradeal-sourcing.pages.dev) | L15: 용정하 | N15: UX/UI 개선 피드백 | O15: 주 2~3회 | P15: 비정형(판단 필요) | Q15: 모름 | R15: 개선 요청·피드백 이력을 앱 내 이슈보드로 관리해 재설명 시간 제거
A16: =IF($B$3="","",$B$3+0) | B16: 월 | C16: 0.625 | D16: 0.64583333 | E16: =IF(OR(C16="",D16=""),"",(D16-C16)*1440) | F16: 채널·스토어운영 | G16: CHN-01 상품 등록·수정(옵션/가격) | H16: 가나랜드(대리점) 스마트스토어 상품등록 요청(란님께) | I16: 가나랜드 / 스마트스토어 | J16: 스마트스토어센터 | L16: 이란 | M16: 가나랜드 | N16: 상품등록 요청 내역 | O16: 주 1회 | P16: 정형(매뉴얼화 가능) | Q16: 예 - 확실히 중복 | R16: 상품 마스터 DB 기준 채널 자동 등록
A17: =IF($B$3="","",$B$3+0) | B17: 월 | C17: 0.64583333 | D17: 0.66666667 | E17: =IF(OR(C17="",D17=""),"",(D17-C17)*1440) | F17: 제조·생산관리 | G17: MFG-06 선적·입고 일정 관리 | H17: 신제품(외벽·슁글·목재·판넬) 생산완료 건 입고 요청(채림님께) | I17: 신제품 4종 | J17: CRM센터-POUR OS(업무보드) | K17: https://pourstorecrm.web.app/pour-os | L17: 양채림 | M17: 생산공장 | N17: 입고 요청 내역 | O17: 주 1회 | P17: 정형(매뉴얼화 가능) | Q17: 아마도 중복 | R17: 생산완료 → 입고요청 자동 알림 연동
A18: =IF($B$3="","",$B$3+0) | B18: 월 | C18: 0.66666667 | D18: 0.70833333 | E18: =IF(OR(C18="",D18=""),"",(D18-C18)*1440) | F18: CS·물류·재고 | G18: OPS-03 재고 현황 점검·발주 요청 | H18: 쿠팡 판매량 확인 및 재고부족 건 입고 요청 / 담당 인수인계 안내(채림님·란님) | I18: POUR스토어 / 쿠팡 | J18: 쿠팡 WING | L18: 양채림, 이란 | N18: 재고·입고 요청 내역 | O18: 매일 | P18: 정형(매뉴얼화 가능) | Q18: 예 - 확실히 중복 | R18: 채널 재고 임계치 도달 시 자동 알림·발주 요청
A19: =IF($B$3="","",$B$3+0) | B19: 월 | C19: 0.70833333 | D19: 0.75 | E19: =IF(OR(C19="",D19=""),"",(D19-C19)*1440) | F19: 마케팅·광고운영 | G19: MKT-04 인플루언서·체험단 섭외/관리 | H19: 퍼포먼스마케팅 인플루언서/셀러 협업 현황 확인 및 컨택 방안 피드백(채림님께) | I19: POUR스토어 | J19: CRM센터-POUR OS(업무보드) | K19: https://pourstorecrm.web.app/pour-os | L19: 양채림 | M19: 인플루언서·셀러 | N19: 협업 컨택 방안 피드백 | O19: 주 1회 | P19: 비정형(판단 필요) | Q19: 아마도 중복 | R19: 인플루언서/셀러 컨택 이력 DB 공용화(중복 컨택 방지)
A20: =IF($B$3="","",$B$3+0) | B20: 월 | E20: =IF(OR(C20="",D20=""),"",(D20-C20)*1440) | K20: https://pourstorecrm.web.app/pour-os
A21: =IF($B$3="","",$B$3+0) | B21: 월 | E21: =IF(OR(C21="",D21=""),"",(D21-C21)*1440)
A22: =IF($B$3="","",$B$3+0) | B22: 월 | E22: =IF(OR(C22="",D22=""),"",(D22-C22)*1440)
A23: =IF($B$3="","",$B$3+0) | B23: 월 | E23: =IF(OR(C23="",D23=""),"",(D23-C23)*1440)
A24: =IF($B$3="","",$B$3+0) | B24: 월 | E24: =IF(OR(C24="",D24=""),"",(D24-C24)*1440)
A25: =IF($B$3="","",$B$3+0) | B25: 월(추가) | E25: =IF(OR(C25="",D25=""),"",(D25-C25)*1440)
A26: =IF($B$3="","",$B$3+0) | B26: 월(추가) | E26: =IF(OR(C26="",D26=""),"",(D26-C26)*1440)
A27: =IF($B$3="","",$B$3+1) | B27: 화 | C27: 0.375 | D27: 0.39583333 | E27: =IF(OR(C27="",D27=""),"",(D27-C27)*1440) | F27: 기타·행정 | G27: ETC-01 메일·메신저 확인 및 회신 | H27: 출근 후 메일·메신저·업무보드 확인 및 회신 | I27: 전사 | J27: CRM센터-POUR OS(업무보드) | K27: https://pourstorecrm.web.app/pour-os | N27: 회신 처리 | O27: 매일 | P27: 정형(매뉴얼화 가능) | Q27: 예 - 확실히 중복 | R27: 팀별 요청·공지를 업무보드 알림 하나로 일원화
A28: =IF($B$3="","",$B$3+1) | B28: 화 | C28: 0.39583333 | D28: 0.45833333 | E28: =IF(OR(C28="",D28=""),"",(D28-C28)*1440) | F28: 기획·보고·회의 | G28: MGT-01 팀 내부 회의 | H28: 모여라딜 피봇팅 방향 논의 및 정하님 업무 진행방향 미팅 | I28: 모여라딜 | K28: https://pourstorecrm.web.app/pour-os | L28: 용정하 | N28: 미팅 결과·업무 방향 메모 | O28: 주 1회 | P28: 비정형(판단 필요) | Q28: 모름 | R28: 논의 결과를 업무보드 프로젝트 카드로 즉시 반영
A29: =IF($B$3="","",$B$3+1) | B29: 화 | C29: 0.45833333 | D29: 0.5 | E29: =IF(OR(C29="",D29=""),"",(D29-C29)*1440) | F29: 콘텐츠제작 | G29: CNT-02 촬영 기획·진행 | H29: 제품시공 촬영 — 테스트촬영 및 대여 탐색, 채림님께 인수인계하여 진행 요청 (아파트·공장·일반주택 대상) | I29: 시공 제품 / 아파트·공장·일반주택 | J29: CRM센터-POUR OS(업무보드) | K29: https://pourstorecrm.web.app/pour-os | L29: 양채림 | N29: 테스트 촬영본, 촬영 진행 요청서 | O29: 1회성 | P29: 비정형(판단 필요) | Q29: 아마도 중복 | R29: 건물유형별 시공 촬영 가이드·촬영 자산 라이브러리 공용화
A30: =IF($B$3="","",$B$3+1) | B30: 화 | C30: 0.5 | D30: 0.54166667 | E30: =IF(OR(C30="",D30=""),"",(D30-C30)*1440) | F30: 기타·행정 | G30: ETC-05 휴게·점심 | H30: 점심 및 휴게 | O30: 매일 | P30: 정형(매뉴얼화 가능) | Q30: 예 - 확실히 중복
A31: =IF($B$3="","",$B$3+1) | B31: 화 | C31: 0.54166667 | D31: 0.58333333 | E31: =IF(OR(C31="",D31=""),"",(D31-C31)*1440) | F31: 마케팅·광고운영 | G31: MKT-04 인플루언서·체험단 섭외/관리 | H31: 채림님 인플루언서 협업마케팅 진행방향 안내 및 멘트 컨펌 | I31: POUR스토어 | J31: 레뷰, 리뷰플레이스 | K31: https://pourstorecrm.web.app/pour-os | L31: 양채림 | M31: 인플루언서 | N31: 협업 진행안 컨펌 | O31: 주 1회 | P31: 비정형(판단 필요) | Q31: 아마도 중복 | R31: 인플루언서 협업 진행 기준(가이드) 문서화 후 위임
A32: =IF($B$3="","",$B$3+1) | B32: 화 | C32: 0.58333333 | D32: 0.625 | E32: =IF(OR(C32="",D32=""),"",(D32-C32)*1440) | F32: 사내시스템·자동화 | G32: SYS-01 사내 시스템·앱 기획/개선 요청 | H32: 소싱앱 UX/UI 개선 — 정하님 추가 고도화 건 2차 피드백 | I32: 소싱앱 | J32: 소싱앱 | K32: 소싱 관리 · 모여라딜 (moyeoradeal-sourcing.pages.dev) | L32: 용정하 | N32: UX/UI 2차 피드백 | O32: 주 2~3회 | P32: 비정형(판단 필요) | Q32: 모름 | R32: 개선 요청·피드백 이력을 앱 내 이슈보드로 관리
A33: =IF($B$3="","",$B$3+1) | B33: 화 | C33: 0.625 | D33: 0.64583333 | E33: =IF(OR(C33="",D33=""),"",(D33-C33)*1440) | F33: 상품기획·소싱 | G33: PLN-01 신상품 아이템 발굴/시장조사 | H33: 부자재(롤링독) 판매 세팅 검토 — 우선순위 재조정으로 보류 | I33: 부자재·안전용품 | K33: https://pour-construction-form.pages.dev/pourstore-pricing-dashboard | N33: 판매 세팅 검토안(보류) | O33: 분기/비정기 | P33: 비정형(판단 필요) | Q33: 아마도 중복 | R33: 부자재 카테고리 소싱 기준 정립 후 일괄 세팅
A34: =IF($B$3="","",$B$3+1) | B34: 화 | C34: 0.64583333 | D34: 0.6875 | E34: =IF(OR(C34="",D34=""),"",(D34-C34)*1440) | F34: 데이터·정산 | G34: DAT-04 리포트·대시보드 작성 | H34: POUR스토어 단가·공헌이익·손익계산 대시보드 제작 — 진행중(전주 이월) | I34: POUR스토어 | J34: 단가 대시보드, 엑셀 | K34: POUR스토어 가격·마진 통합 대시보드 (pour-construction-form.pages.dev) | N34: 단가·공헌이익·손익 대시보드 | O34: 주 2~3회 | P34: 비정형(판단 필요) | Q34: 아마도 중복 | R34: 채널 수수료·원가 데이터 자동 연동으로 수기 입력 제거
A35: =IF($B$3="","",$B$3+1) | B35: 화 | C35: 0.6875 | D35: 0.75 | E35: =IF(OR(C35="",D35=""),"",(D35-C35)*1440) | F35: 제조·생산관리 | G35: MFG-08 MSDS·라벨 등 제품 표시사항 제작 | H35: 신제품 코트재 MSDS 컬러별 31개 제작 — 진행중 | I35: 코트재 신제품 31색 | J35: 챗지피티 | M35: 세이고, 쿠팡물류센터 | N35: MSDS 31종 | O35: 1회성 | P35: 반정형 | Q35: 아니오 - 우리팀 고유 | R35: 품목·색상 데이터 연동으로 MSDS 서식 자동 생성
A36: =IF($B$3="","",$B$3+1) | B36: 화 | E36: =IF(OR(C36="",D36=""),"",(D36-C36)*1440)
A37: =IF($B$3="","",$B$3+1) | B37: 화 | E37: =IF(OR(C37="",D37=""),"",(D37-C37)*1440)
A38: =IF($B$3="","",$B$3+1) | B38: 화 | E38: =IF(OR(C38="",D38=""),"",(D38-C38)*1440)
A39: =IF($B$3="","",$B$3+1) | B39: 화 | E39: =IF(OR(C39="",D39=""),"",(D39-C39)*1440)
A40: =IF($B$3="","",$B$3+1) | B40: 화 | E40: =IF(OR(C40="",D40=""),"",(D40-C40)*1440)
...

Sheet 03_통합데이터
A1: 전사 취합 데이터 — 3개 팀 전원의 02시트 작성분을 여기에 '값'으로 붙여넣기 (3행부터)
A2: 소속팀 | B2: 이름 | C2: 직위/직무 | D2: 일자 | E2: 요일 | F2: 시작 | G2: 종료 | H2: 소요(분) | I2: 업무 대분류 | J2: 업무 중분류 | K2: 업무 내용 | L2: 대상 브랜드/상품/채널 | M2: 사용 시스템·툴 | N2: 사용 시스템·툴 링크 | O2: 협업 대상(사내) | P2: 협업 대상(사외) | Q2: 산출물 | R2: 반복주기 | S2: 업무 성격 | T2: 타팀 중복예상 | U2: 개선·자동화 아이디어
A3: 브랜드커머스 | B3: 김송희 | C3: 브랜드커머스, 모여라딜 리드 | D3: 46244 | E3: 월 | F3: 0.375 | G3: 0.39583333 | H3: =IF(OR(F3="",G3=""),"",(G3-F3)*1440) | I3: 기타·행정 | J3: ETC-01 메일·메신저 확인 및 회신 | K3: 출근 후 메일·메신저·업무보드 확인 및 회신 | L3: 전사 | M3: CRM센터-POUR OS(업무보드) | N3: https://pourstorecrm.web.app/pour-os | Q3: 회신 처리 | R3: 매일 | S3: 정형(매뉴얼화 가능) | T3: 예 - 확실히 중복 | U3: 팀별 요청·공지를 업무보드 알림 하나로 일원화
A4: 브랜드커머스 | B4: 김송희 | C4: 브랜드커머스, 모여라딜 리드 | D4: 46244 | E4: 월 | F4: 0.39583333 | G4: 0.41666667 | H4: =IF(OR(F4="",G4=""),"",(G4-F4)*1440) | I4: 데이터·정산 | J4: OPS-06 일일 주문,매출 확인 | K4: 금일 주문,매출 확인 | L4: POUR스토어 / 자사몰·오픈마켓 | M4: 사방넷 | Q4: 일일 주문 확인 내역 | R4: 매일 | S4: 정형(매뉴얼화 가능) | T4: 예 - 확실히 중복 | U4: 채널별 주문을 통합 주문판으로 자동 취합
A5: 브랜드커머스 | B5: 김송희 | C5: 브랜드커머스, 모여라딜 리드 | D5: 46244 | E5: 월 | F5: 0.41666667 | G5: 0.45833333 | H5: =IF(OR(F5="",G5=""),"",(G5-F5)*1440) | I5: 마케팅·광고운영 | J5: MKT-08 제휴마케팅(링크프라이스 등) 운영·성과확인 | K5: 링크프라이스 제휴광고 집행 현황 확인 및 신제품 검색 시 상위노출 여부 점검 | L5: POUR스토어 / 링크프라이스·네이버쇼핑 | M5: 링크프라이스 관리자, 네이버쇼핑 | P5: 링크프라이스 | Q5: 제휴광고 현황 점검 메모 | R5: 주 1회 | S5: 반정형 | T5: 아마도 중복 | U5: 제휴·검색광고 성과를 본부 공용 대시보드로 자동 수집
A6: 브랜드커머스 | B6: 김송희 | C6: 브랜드커머스, 모여라딜 리드 | D6: 46244 | E6: 월 | F6: 0.45833333 | G6: 0.47916667 | H6: =IF(OR(F6="",G6=""),"",(G6-F6)*1440) | I6: 마케팅·광고운영 | J6: MKT-05 프로모션·기획전 기획 | K6: 8월 프로모션 기획 요청 — 민지님께 기획 방향 전달 및 작성 요청 | L6: POUR스토어 | M6: CRM센터-POUR OS(업무보드) | N6: https://pourstorecrm.web.app/pour-os | O6: 김민지 | Q6: 프로모션 기획 요청서 | R6: 월 1회 | S6: 반정형 | T6: 아마도 중복 | U6: 프로모션 기획 요청 양식 표준화 + 본부 공용 프로모션 캘린더
A7: 브랜드커머스 | B7: 김송희 | C7: 브랜드커머스, 모여라딜 리드 | D7: 46244 | E7: 월 | F7: 0.47916667 | G7: 0.5 | H7: =IF(OR(F7="",G7=""),"",(G7-F7)*1440) | I7: 파트너·대리점관리 | J7: PTR-02 대리점·파트너 인터뷰·VOC 수집 | K7: 금요일 부산 대리점 방문 미팅·인터뷰 질문지 제작 요청(란님께) | L7: 대리점(가나랜드·경남지사) | M7: CRM센터-POUR OS(업무보드) | N7: https://pourstorecrm.web.app/pour-os | O7: 이란 | Q7: 대리점 인터뷰 질문지 | R7: 분기/비정기 | S7: 반정형 | T7: 모름 | U7: 대리점 인터뷰 질문지 표준 템플릿화
A8: 브랜드커머스 | B8: 김송희 | C8: 브랜드커머스, 모여라딜 리드 | D8: 46244 | E8: 월 | F8: 0.5 | G8: 0.54166667 | H8: =IF(OR(F8="",G8=""),"",(G8-F8)*1440) | I8: 기타·행정 | J8: ETC-05 휴게·점심 | K8: 점심 및 휴게 | R8: 매일 | S8: 정형(매뉴얼화 가능) | T8: 예 - 확실히 중복
A9: 브랜드커머스 | B9: 김송희 | C9: 브랜드커머스, 모여라딜 리드 | D9: 46244 | E9: 월 | F9: 0.54166667 | G9: 0.5625 | H9: =IF(OR(F9="",G9=""),"",(G9-F9)*1440) | I9: 사내시스템·자동화 | J9: SYS-01 사내 시스템·앱 기획/개선 요청 | K9: CRM센터 NPS 기능 개선 요청 — 채림님께 개선 항목 정리·전달 | L9: CRM센터 | M9: CRM센터 | N9: https://pourstorecrm.web.app/pour-os | O9: 양채림 | Q9: 기능 개선 요청 내역 | R9: 주 1회 | S9: 반정형 | T9: 모름 | U9: 사내 시스템 개선 요청을 티켓(이슈보드)으로 단일 창구화
A10: 브랜드커머스 | B10: 김송희 | C10: 브랜드커머스, 모여라딜 리드 | D10: 46244 | E10: 월 | F10: 0.5625 | G10: 0.58333333 | H10: =IF(OR(F10="",G10=""),"",(G10-F10)*1440) | I10: 사내시스템·자동화 | J10: SYS-01 사내 시스템·앱 기획/개선 요청 | K10: 소싱앱 기능 고도화 요청-운전하면서도 쉽고빠르게 사용가능하게(정하님께) | L10: 소싱앱 | M10: 소싱앱 | N10: 소싱 관리 · 모여라딜 (moyeoradeal-sourcing.pages.dev) | O10: 용정하 | Q10: 기능 고도화 요청 내역 | R10: 주 1회 | S10: 반정형 | T10: 모름 | U10: 사내 시스템 개선 요청을 티켓(이슈보드)으로 단일 창구화
A11: 브랜드커머스 | B11: 김송희 | C11: 브랜드커머스, 모여라딜 리드 | D11: 46244 | E11: 월 | F11: 0.58333333 | G11: 0.625 | H11: =IF(OR(F11="",G11=""),"",(G11-F11)*1440) | I11: 사내시스템·자동화 | J11: SYS-01 사내 시스템·앱 기획/개선 요청 | K11: 소싱앱 UX/UI 개선 — 정하님 추가 고도화 건 화면별 피드백 작성 | L11: 소싱앱 | M11: 소싱앱 | N11: 소싱 관리 · 모여라딜 (moyeoradeal-sourcing.pages.dev) | O11: 용정하 | Q11: UX/UI 개선 피드백 | R11: 주 2~3회 | S11: 비정형(판단 필요) | T11: 모름 | U11: 개선 요청·피드백 이력을 앱 내 이슈보드로 관리해 재설명 시간 제거
A12: 브랜드커머스 | B12: 김송희 | C12: 브랜드커머스, 모여라딜 리드 | D12: 46244 | E12: 월 | F12: 0.625 | G12: 0.64583333 | H12: =IF(OR(F12="",G12=""),"",(G12-F12)*1440) | I12: 채널·스토어운영 | J12: CHN-01 상품 등록·수정(옵션/가격) | K12: 가나랜드(대리점) 스마트스토어 상품등록 요청(란님께) | L12: 가나랜드 / 스마트스토어 | M12: 스마트스토어센터 | O12: 이란 | P12: 가나랜드 | Q12: 상품등록 요청 내역 | R12: 주 1회 | S12: 정형(매뉴얼화 가능) | T12: 예 - 확실히 중복 | U12: 상품 마스터 DB 기준 채널 자동 등록
A13: 브랜드커머스 | B13: 김송희 | C13: 브랜드커머스, 모여라딜 리드 | D13: 46244 | E13: 월 | F13: 0.64583333 | G13: 0.66666667 | H13: =IF(OR(F13="",G13=""),"",(G13-F13)*1440) | I13: 제조·생산관리 | J13: MFG-06 선적·입고 일정 관리 | K13: 신제품(외벽·슁글·목재·판넬) 생산완료 건 입고 요청(채림님께) | L13: 신제품 4종 | M13: CRM센터-POUR OS(업무보드) | N13: https://pourstorecrm.web.app/pour-os | O13: 양채림 | P13: 생산공장 | Q13: 입고 요청 내역 | R13: 주 1회 | S13: 정형(매뉴얼화 가능) | T13: 아마도 중복 | U13: 생산완료 → 입고요청 자동 알림 연동
A14: 브랜드커머스 | B14: 김송희 | C14: 브랜드커머스, 모여라딜 리드 | D14: 46244 | E14: 월 | F14: 0.66666667 | G14: 0.70833333 | H14: =IF(OR(F14="",G14=""),"",(G14-F14)*1440) | I14: CS·물류·재고 | J14: OPS-03 재고 현황 점검·발주 요청 | K14: 쿠팡 판매량 확인 및 재고부족 건 입고 요청 / 담당 인수인계 안내(채림님·란님) | L14: POUR스토어 / 쿠팡 | M14: 쿠팡 WING | O14: 양채림, 이란 | Q14: 재고·입고 요청 내역 | R14: 매일 | S14: 정형(매뉴얼화 가능) | T14: 예 - 확실히 중복 | U14: 채널 재고 임계치 도달 시 자동 알림·발주 요청
A15: 브랜드커머스 | B15: 김송희 | C15: 브랜드커머스, 모여라딜 리드 | D15: 46244 | E15: 월 | F15: 0.70833333 | G15: 0.75 | H15: =IF(OR(F15="",G15=""),"",(G15-F15)*1440) | I15: 마케팅·광고운영 | J15: MKT-04 인플루언서·체험단 섭외/관리 | K15: 퍼포먼스마케팅 인플루언서/셀러 협업 현황 확인 및 컨택 방안 피드백(채림님께) | L15: POUR스토어 | M15: CRM센터-POUR OS(업무보드) | N15: https://pourstorecrm.web.app/pour-os | O15: 양채림 | P15: 인플루언서·셀러 | Q15: 협업 컨택 방안 피드백 | R15: 주 1회 | S15: 비정형(판단 필요) | T15: 아마도 중복 | U15: 인플루언서/셀러 컨택 이력 DB 공용화(중복 컨택 방지)
A16: 브랜드커머스 | B16: 김송희 | C16: 브랜드커머스, 모여라딜 리드 | D16: 46245 | E16: 화 | F16: 0.375 | G16: 0.39583333 | H16: =IF(OR(F16="",G16=""),"",(G16-F16)*1440) | I16: 기타·행정 | J16: ETC-01 메일·메신저 확인 및 회신 | K16: 출근 후 메일·메신저·업무보드 확인 및 회신 | L16: 전사 | M16: CRM센터-POUR OS(업무보드) | N16: https://pourstorecrm.web.app/pour-os | Q16: 회신 처리 | R16: 매일 | S16: 정형(매뉴얼화 가능) | T16: 예 - 확실히 중복 | U16: 팀별 요청·공지를 업무보드 알림 하나로 일원화
A17: 브랜드커머스 | B17: 김송희 | C17: 브랜드커머스, 모여라딜 리드 | D17: 46245 | E17: 화 | F17: 0.39583333 | G17: 0.45833333 | H17: =IF(OR(F17="",G17=""),"",(G17-F17)*1440) | I17: 기획·보고·회의 | J17: MGT-01 팀 내부 회의 | K17: 모여라딜 피봇팅 방향 논의 및 정하님 업무 진행방향 미팅 | L17: 모여라딜 | N17: https://pourstorecrm.web.app/pour-os | O17: 용정하 | Q17: 미팅 결과·업무 방향 메모 | R17: 주 1회 | S17: 비정형(판단 필요) | T17: 모름 | U17: 논의 결과를 업무보드 프로젝트 카드로 즉시 반영
A18: 브랜드커머스 | B18: 김송희 | C18: 브랜드커머스, 모여라딜 리드 | D18: 46245 | E18: 화 | F18: 0.45833333 | G18: 0.5 | H18: =IF(OR(F18="",G18=""),"",(G18-F18)*1440) | I18: 콘텐츠제작 | J18: CNT-02 촬영 기획·진행 | K18: 제품시공 촬영 — 테스트촬영 및 대여 탐색, 채림님께 인수인계하여 진행 요청 (아파트·공장·일반주택 대상) | L18: 시공 제품 / 아파트·공장·일반주택 | M18: CRM센터-POUR OS(업무보드) | N18: https://pourstorecrm.web.app/pour-os | O18: 양채림 | Q18: 테스트 촬영본, 촬영 진행 요청서 | R18: 1회성 | S18: 비정형(판단 필요) | T18: 아마도 중복 | U18: 건물유형별 시공 촬영 가이드·촬영 자산 라이브러리 공용화
A19: 브랜드커머스 | B19: 김송희 | C19: 브랜드커머스, 모여라딜 리드 | D19: 46245 | E19: 화 | F19: 0.5 | G19: 0.54166667 | H19: =IF(OR(F19="",G19=""),"",(G19-F19)*1440) | I19: 기타·행정 | J19: ETC-05 휴게·점심 | K19: 점심 및 휴게 | R19: 매일 | S19: 정형(매뉴얼화 가능) | T19: 예 - 확실히 중복
A20: 브랜드커머스 | B20: 김송희 | C20: 브랜드커머스, 모여라딜 리드 | D20: 46245 | E20: 화 | F20: 0.54166667 | G20: 0.58333333 | H20: =IF(OR(F20="",G20=""),"",(G20-F20)*1440) | I20: 마케팅·광고운영 | J20: MKT-04 인플루언서·체험단 섭외/관리 | K20: 채림님 인플루언서 협업마케팅 진행방향 안내 및 멘트 컨펌 | L20: POUR스토어 | M20: 레뷰, 리뷰플레이스 | N20: https://pourstorecrm.web.app/pour-os | O20: 양채림 | P20: 인플루언서 | Q20: 협업 진행안 컨펌 | R20: 주 1회 | S20: 비정형(판단 필요) | T20: 아마도 중복 | U20: 인플루언서 협업 진행 기준(가이드) 문서화 후 위임
A21: 브랜드커머스 | B21: 김송희 | C21: 브랜드커머스, 모여라딜 리드 | D21: 46245 | E21: 화 | F21: 0.58333333 | G21: 0.625 | H21: =IF(OR(F21="",G21=""),"",(G21-F21)*1440) | I21: 사내시스템·자동화 | J21: SYS-01 사내 시스템·앱 기획/개선 요청 | K21: 소싱앱 UX/UI 개선 — 정하님 추가 고도화 건 2차 피드백 | L21: 소싱앱 | M21: 소싱앱 | N21: 소싱 관리 · 모여라딜 (moyeoradeal-sourcing.pages.dev) | O21: 용정하 | Q21: UX/UI 2차 피드백 | R21: 주 2~3회 | S21: 비정형(판단 필요) | T21: 모름 | U21: 개선 요청·피드백 이력을 앱 내 이슈보드로 관리
A22: 브랜드커머스 | B22: 김송희 | C22: 브랜드커머스, 모여라딜 리드 | D22: 46245 | E22: 화 | F22: 0.625 | G22: 0.64583333 | H22: =IF(OR(F22="",G22=""),"",(G22-F22)*1440) | I22: 상품기획·소싱 | J22: PLN-01 신상품 아이템 발굴/시장조사 | K22: 부자재(롤링독) 판매 세팅 검토 — 우선순위 재조정으로 보류 | L22: 부자재·안전용품 | N22: https://pour-construction-form.pages.dev/pourstore-pricing-dashboard | Q22: 판매 세팅 검토안(보류) | R22: 분기/비정기 | S22: 비정형(판단 필요) | T22: 아마도 중복 | U22: 부자재 카테고리 소싱 기준 정립 후 일괄 세팅
A23: 브랜드커머스 | B23: 김송희 | C23: 브랜드커머스, 모여라딜 리드 | D23: 46245 | E23: 화 | F23: 0.64583333 | G23: 0.6875 | H23: =IF(OR(F23="",G23=""),"",(G23-F23)*1440) | I23: 데이터·정산 | J23: DAT-04 리포트·대시보드 작성 | K23: POUR스토어 단가·공헌이익·손익계산 대시보드 제작 — 진행중(전주 이월) | L23: POUR스토어 | M23: 단가 대시보드, 엑셀 | N23: POUR스토어 가격·마진 통합 대시보드 (pour-construction-form.pages.dev) | Q23: 단가·공헌이익·손익 대시보드 | R23: 주 2~3회 | S23: 비정형(판단 필요) | T23: 아마도 중복 | U23: 채널 수수료·원가 데이터 자동 연동으로 수기 입력 제거
A24: 브랜드커머스 | B24: 김송희 | C24: 브랜드커머스, 모여라딜 리드 | D24: 46245 | E24: 화 | F24: 0.6875 | G24: 0.75 | H24: =IF(OR(F24="",G24=""),"",(G24-F24)*1440) | I24: 제조·생산관리 | J24: MFG-08 MSDS·라벨 등 제품 표시사항 제작 | K24: 신제품 코트재 MSDS 컬러별 31개 제작 — 진행중 | L24: 코트재 신제품 31색 | M24: 챗지피티 | P24: 세이고, 쿠팡물류센터 | Q24: MSDS 31종 | R24: 1회성 | S24: 반정형 | T24: 아니오 - 우리팀 고유 | U24: 품목·색상 데이터 연동으로 MSDS 서식 자동 생성
A25: 브랜드커머스 | B25: 김송희 | C25: 브랜드커머스, 모여라딜 리드 | D25: 46246 | E25: 수 | F25: 0.375 | G25: 0.39583333 | H25: =IF(OR(F25="",G25=""),"",(G25-F25)*1440) | I25: 기타·행정 | J25: ETC-01 메일·메신저 확인 및 회신 | K25: 출근 후 메일·메신저·업무보드 확인 및 회신 | L25: 전사 | M25: CRM센터-POUR OS(업무보드) | N25: https://pourstorecrm.web.app/pour-os | Q25: 회신 처리 | R25: 매일 | S25: 정형(매뉴얼화 가능) | T25: 예 - 확실히 중복 | U25: 팀별 요청·공지를 업무보드 알림 하나로 일원화
A26: 브랜드커머스 | B26: 김송희 | C26: 브랜드커머스, 모여라딜 리드 | D26: 46246 | E26: 수 | F26: 0.39583333 | G26: 0.4375 | H26: =IF(OR(F26="",G26=""),"",(G26-F26)*1440) | I26: 파트너·대리점관리 | J26: PTR-01 대리점·파트너사 방문·미팅 | K26: 부산 대리점 방문 준비 — 촬영물품 및 미팅·인터뷰 질문지 최종 확인 | L26: 대리점(가나랜드·경남지사) | M26: CRM센터-POUR OS(업무보드) | N26: https://pourstorecrm.web.app/pour-os | O26: 이란 | P26: 가나랜드, 경남지사 | Q26: 방문 준비 체크리스트 | R26: 분기/비정기 | S26: 반정형 | T26: 모름 | U26: 대리점 방문 준비 체크리스트 표준화
A27: 브랜드커머스 | B27: 김송희 | C27: 브랜드커머스, 모여라딜 리드 | D27: 46246 | E27: 수 | F27: 0.4375 | G27: 0.47916667 | H27: =IF(OR(F27="",G27=""),"",(G27-F27)*1440) | I27: 마케팅·광고운영 | J27: MKT-05 프로모션·기획전 기획 | K27: 스토어 8~10월 프로모션 기획안 검토 및 피드백(민지님) | L27: POUR스토어 | M27: CRM센터-POUR OS(업무보드) | N27: https://pourstorecrm.web.app/pour-os | O27: 김민지 | Q27: 프로모션 기획 피드백 | R27: 월 1회 | S27: 반정형 | T27: 아마도 중복 | U27: 본부 공용 프로모션 캘린더로 3팀 일정·중복 방지
A28: 브랜드커머스 | B28: 김송희 | C28: 브랜드커머스, 모여라딜 리드 | D28: 46246 | E28: 수 | F28: 0.47916667 | G28: 0.5 | H28: =IF(OR(F28="",G28=""),"",(G28-F28)*1440) | I28: 마케팅·광고운영 | J28: MKT-02 광고 성과 모니터링·최적화 | K28: 신제품(철재페인트) 키워드광고 상위노출 확인 | L28: 신제품 철재페인트 / 네이버 | M28: 네이버 검색, 검색광고 관리자 | Q28: 노출 순위 점검 메모 | R28: 주 2~3회 | S28: 정형(매뉴얼화 가능) | T28: 예 - 확실히 중복 | U28: 키워드 순위 자동 추적 리포트로 대체
A29: 브랜드커머스 | B29: 김송희 | C29: 브랜드커머스, 모여라딜 리드 | D29: 46246 | E29: 수 | F29: 0.5 | G29: 0.54166667 | H29: =IF(OR(F29="",G29=""),"",(G29-F29)*1440) | I29: 기타·행정 | J29: ETC-05 휴게·점심 | K29: 점심 및 휴게 | R29: 매일 | S29: 정형(매뉴얼화 가능) | T29: 예 - 확실히 중복
A30: 브랜드커머스 | B30: 김송희 | C30: 브랜드커머스, 모여라딜 리드 | D30: 46246 | E30: 수 | F30: 0.54166667 | G30: 0.58333333 | H30: =IF(OR(F30="",G30=""),"",(G30-F30)*1440) | I30: 기획·보고·회의 | J30: MGT-06 팀원 업무·산출물 검토·피드백 | K30: AX+업무리스트 보고서 검토 및 피드백(정하님) | L30: 팀 업무관리 | M30: CRM센터-POUR OS(업무보드) | N30: https://pourstorecrm.web.app/pour-os | O30: 용정하 | Q30: 검토 피드백 | R30: 주 1회 | S30: 비정형(판단 필요) | T30: 아마도 중복 | U30: 업무보드 데이터 자동 집계로 보고서 수기작성 제거
A31: 브랜드커머스 | B31: 김송희 | C31: 브랜드커머스, 모여라딜 리드 | D31: 46246 | E31: 수 | F31: 0.58333333 | G31: 0.60416667 | H31: =IF(OR(F31="",G31=""),"",(G31-F31)*1440) | I31: 기획·보고·회의 | J31: MGT-06 팀원 업무·산출물 검토·피드백 | K31: AX+업무리스트 보고서 검토 및 피드백(채림님) | L31: 팀 업무관리 | M31: CRM센터-POUR OS(업무보드) | N31: https://pourstorecrm.web.app/pour-os | O31: 양채림 | Q31: 검토 피드백 | R31: 주 1회 | S31: 비정형(판단 필요) | T31: 아마도 중복 | U31: 업무보드 데이터 자동 집계로 보고서 수기작성 제거
A32: 브랜드커머스 | B32: 김송희 | C32: 브랜드커머스, 모여라딜 리드 | D32: 46246 | E32: 수 | F32: 0.60416667 | G32: 0.64583333 | H32: =IF(OR(F32="",G32=""),"",(G32-F32)*1440) | I32: 기획·보고·회의 | J32: MGT-07 업무 인수인계·이관 | K32: 그로홈 업무 인수인계 받음 — 담당 범위·진행건 확인 | L32: 그로홈 | M32: CRM센터-POUR OS(업무보드) | N32: https://pourstorecrm.web.app/pour-os | Q32: 인수인계 항목 정리 | R32: 1회성 | S32: 비정형(판단 필요) | T32: 모름 | U32: 인수인계 체크리스트·담당 매핑표 상시 관리
A33: 브랜드커머스 | B33: 김송희 | C33: 브랜드커머스, 모여라딜 리드 | D33: 46246 | E33: 수 | F33: 0.64583333 | G33: 0.6875 | H33: =IF(OR(F33="",G33=""),"",(G33-F33)*1440) | I33: 콘텐츠제작 | J33: CNT-07 카탈로그·영업자료 제작 | K33: 부자재 소개 카달로그 제작 | L33: 부자재 | Q33: 부자재 소개 카달로그 | R33: 1회성 | S33: 반정형 | T33: 아마도 중복 | U33: 상품 마스터 데이터로 카달로그 자동 생성
A34: 브랜드커머스 | B34: 김송희 | C34: 브랜드커머스, 모여라딜 리드 | D34: 46246 | E34: 수 | F34: 0.6875 | G34: 0.72916667 | H34: =IF(OR(F34="",G34=""),"",(G34-F34)*1440) | I34: 데이터·정산 | J34: DAT-04 리포트·대시보드 작성 | K34: POUR스토어 단가·공헌이익·손익계산 대시보드 제작 — 진행중 | L34: POUR스토어 | M34: 단가 대시보드, 엑셀 | N34: POUR스토어 가격·마진 통합 대시보드 (pour-construction-form.pages.dev) | Q34: 단가·공헌이익·손익 대시보드 | R34: 주 2~3회 | S34: 비정형(판단 필요) | T34: 아마도 중복 | U34: 채널 수수료·원가 데이터 자동 연동으로 수기 입력 제거
A35: 브랜드커머스 | B35: 김송희 | C35: 브랜드커머스, 모여라딜 리드 | D35: 46246 | E35: 수 | F35: 0.72916667 | G35: 0.75 | H35: =IF(OR(F35="",G35=""),"",(G35-F35)*1440) | I35: 제조·생산관리 | J35: MFG-08 MSDS·라벨 등 제품 표시사항 제작 | K35: 신제품 코트재 MSDS 컬러별 31개 제작 — 진행중 | L35: 코트재 신제품 31색 | M35: 챗지피티 | P35: 세이고, 쿠팡물류센터 | Q35: MSDS 31종 | R35: 1회성 | S35: 반정형 | T35: 아니오 - 우리팀 고유 | U35: 품목·색상 데이터 연동으로 MSDS 서식 자동 생성
A36: 브랜드커머스 | B36: 김송희 | C36: 브랜드커머스, 모여라딜 리드 | D36: 46247 | E36: 목 | F36: 0.375 | G36: 0.39583333 | H36: =IF(OR(F36="",G36=""),"",(G36-F36)*1440) | I36: 기타·행정 | J36: ETC-01 메일·메신저 확인 및 회신 | K36: 출근 후 메일·메신저·업무보드 확인 및 회신 | L36: 전사 | M36: CRM센터-POUR OS(업무보드) | N36: https://pourstorecrm.web.app/pour-os | Q36: 회신 처리 | R36: 매일 | S36: 정형(매뉴얼화 가능) | T36: 예 - 확실히 중복 | U36: 팀별 요청·공지를 업무보드 알림 하나로 일원화
A37: 브랜드커머스 | B37: 김송희 | C37: 브랜드커머스, 모여라딜 리드 | D37: 46247 | E37: 목 | F37: 0.39583333 | G37: 0.4375 | H37: =IF(OR(F37="",G37=""),"",(G37-F37)*1440) | I37: 마케팅·광고운영 | J37: MKT-08 제휴마케팅(링크프라이스 등) 운영·성과확인 | K37: 링크프라이스 네이버쇼핑·파워링크 주간보고 수령 → 본부장님 보고 → 보성님 인계 | L37: POUR스토어 / 네이버쇼핑·파워링크 | M37: 링크프라이스 관리자 | O37: 본부장, 보성님 | P37: 링크프라이스 | Q37: 제휴·검색광고 주간보고 | R37: 주 1회 | S37: 정형(매뉴얼화 가능) | T37: 예 - 확실히 중복 | U37: 주간보고 자동 생성 후 공유(수령→전달 단계 제거)
A38: 브랜드커머스 | B38: 김송희 | C38: 브랜드커머스, 모여라딜 리드 | D38: 46247 | E38: 목 | F38: 0.4375 | G38: 0.47916667 | H38: =IF(OR(F38="",G38=""),"",(G38-F38)*1440) | I38: 기타·행정 | J38: ETC-02 행정·경비·구매 처리 | K38: 씰맥스프로 결제 처리 및 세이고 입고내역 자료 송부(김성준 공장장님께) | L38: 씰맥스프로 / 세이고 | O38: 김성준 공장장 | P38: 세이고 | Q38: 결제 완료·입고내역 자료 | R38: 주 1회 | S38: 정형(매뉴얼화 가능) | T38: 아마도 중복 | U38: 결제·입고내역 자동 정산 시트 연동
A39: 브랜드커머스 | B39: 김송희 | C39: 브랜드커머스, 모여라딜 리드 | D39: 46247 | E39: 목 | F39: 0.47916667 | G39: 0.5 | H39: =IF(OR(F39="",G39=""),"",(G39-F39)*1440) | I39: 기획·보고·회의 | J39: MGT-06 팀원 업무·산출물 검토·피드백 | K39: 정하님 업무정리 리스트 검토 | L39: 팀 업무관리 | M39: CRM센터-POUR OS(업무보드) | N39: https://pourstorecrm.web.app/pour-os | O39: 용정하 | Q39: 검토 의견 | R39: 주 1회 | S39: 비정형(판단 필요) | T39: 아마도 중복 | U39: 업무보드 데이터 자동 집계로 대체
A40: 브랜드커머스 | B40: 김송희 | C40: 브랜드커머스, 모여라딜 리드 | D40: 46247 | E40: 목 | F40: 0.5 | G40: 0.54166667 | H40: =IF(OR(F40="",G40=""),"",(G40-F40)*1440) | I40: 기타·행정 | J40: ETC-05 휴게·점심 | K40: 점심 및 휴게 | R40: 매일 | S40: 정형(매뉴얼화 가능) | T40: 예 - 확실히 중복
...

Sheet 04_중복업무분석
A1: 중복업무 자동 분석 — 03_통합데이터 입력 시 자동 계산
A3: 총 기록 건수 | C3: 총 기록 시간(h) | E3: 미디어커머스(h) | G3: 브랜드커머스(h) | I3: 해외제조(h)
A4: =COUNTA('03_통합데이터'!$J$3:$J$1002) | C4: =ROUND(SUM('03_통합데이터'!$H$3:$H$1002)/60,1) | E4: =ROUND(SUMIF('03_통합데이터'!$A$3:$A$1002,"미디어커머스",'03_통합데이터'!$H$3:$H$1002)/60,1) | G4: =ROUND(SUMIF('03_통합데이터'!$A$3:$A$1002,"브랜드커머스",'03_통합데이터'!$H$3:$H$1002)/60,1) | I4: =ROUND(SUMIF('03_통합데이터'!$A$3:$A$1002,"해외제조",'03_통합데이터'!$H$3:$H$1002)/60,1)
A6: 업무 대분류 | B6: 업무 중분류 | C6: 미디어커머스 (분) | D6: 브랜드커머스 (분) | E6: 해외제조 (분) | F6: 합계(분) | G6: 합계(h) | H6: 수행 팀수 | I6: 기록 건수 | J6: 중복 판정 | K6: 통합 우선순위점수
A7: 상품기획·소싱 | B7: PLN-01 신상품 아이템 발굴/시장조사 | C7: =SUMIFS('03_통합데이터'!$H$3:$H$1002,'03_통합데이터'!$J$3:$J$1002,$B7,'03_통합데이터'!$A$3:$A$1002,"미디어커머스") | D7: =SUMIFS('03_통합데이터'!$H$3:$H$1002,'03_통합데이터'!$J$3:$J$1002,$B7,'03_통합데이터'!$A$3:$A$1002,"브랜드커머스") | E7: =SUMIFS('03_통합데이터'!$H$3:$H$1002,'03_통합데이터'!$J$3:$J$1002,$B7,'03_통합데이터'!$A$3:$A$1002,"해외제조") | F7: =SUM(C7:E7) | G7: =ROUND(F7/60,1) | H7: =IF(C7>0,1,0)+IF(D7>0,1,0)+IF(E7>0,1,0) | I7: =COUNTIF('03_통합데이터'!$J$3:$J$1002,$B7) | J7: =IF(H7>=3,"◎ 3개팀 중복",IF(H7=2,"○ 2개팀 중복",IF(H7=1,"단독 수행","미기록"))) | K7: =IF(H7>=2,ROUND(H7*G7,1),0)
A8: 상품기획·소싱 | B8: PLN-02 경쟁사·트렌드 분석 | C8: =SUMIFS('03_통합데이터'!$H$3:$H$1002,'03_통합데이터'!$J$3:$J$1002,$B8,'03_통합데이터'!$A$3:$A$1002,"미디어커머스") | D8: =SUMIFS('03_통합데이터'!$H$3:$H$1002,'03_통합데이터'!$J$3:$J$1002,$B8,'03_통합데이터'!$A$3:$A$1002,"브랜드커머스") | E8: =SUMIFS('03_통합데이터'!$H$3:$H$1002,'03_통합데이터'!$J$3:$J$1002,$B8,'03_통합데이터'!$A$3:$A$1002,"해외제조") | F8: =SUM(C8:E8) | G8: =ROUND(F8/60,1) | H8: =IF(C8>0,1,0)+IF(D8>0,1,0)+IF(E8>0,1,0) | I8: =COUNTIF('03_통합데이터'!$J$3:$J$1002,$B8) | J8: =IF(H8>=3,"◎ 3개팀 중복",IF(H8=2,"○ 2개팀 중복",IF(H8=1,"단독 수행","미기록"))) | K8: =IF(H8>=2,ROUND(H8*G8,1),0)
A9: 상품기획·소싱 | B9: PLN-03 원가·판가(마진) 설계 | C9: =SUMIFS('03_통합데이터'!$H$3:$H$1002,'03_통합데이터'!$J$3:$J$1002,$B9,'03_통합데이터'!$A$3:$A$1002,"미디어커머스") | D9: =SUMIFS('03_통합데이터'!$H$3:$H$1002,'03_통합데이터'!$J$3:$J$1002,$B9,'03_통합데이터'!$A$3:$A$1002,"브랜드커머스") | E9: =SUMIFS('03_통합데이터'!$H$3:$H$1002,'03_통합데이터'!$J$3:$J$1002,$B9,'03_통합데이터'!$A$3:$A$1002,"해외제조") | F9: =SUM(C9:E9) | G9: =ROUND(F9/60,1) | H9: =IF(C9>0,1,0)+IF(D9>0,1,0)+IF(E9>0,1,0) | I9: =COUNTIF('03_통합데이터'!$J$3:$J$1002,$B9) | J9: =IF(H9>=3,"◎ 3개팀 중복",IF(H9=2,"○ 2개팀 중복",IF(H9=1,"단독 수행","미기록"))) | K9: =IF(H9>=2,ROUND(H9*G9,1),0)
A10: 상품기획·소싱 | B10: PLN-04 공급처(벤더) 발굴·컨택 | C10: =SUMIFS('03_통합데이터'!$H$3:$H$1002,'03_통합데이터'!$J$3:$J$1002,$B10,'03_통합데이터'!$A$3:$A$1002,"미디어커머스") | D10: =SUMIFS('03_통합데이터'!$H$3:$H$1002,'03_통합데이터'!$J$3:$J$1002,$B10,'03_통합데이터'!$A$3:$A$1002,"브랜드커머스") | E10: =SUMIFS('03_통합데이터'!$H$3:$H$1002,'03_통합데이터'!$J$3:$J$1002,$B10,'03_통합데이터'!$A$3:$A$1002,"해외제조") | F10: =SUM(C10:E10) | G10: =ROUND(F10/60,1) | H10: =IF(C10>0,1,0)+IF(D10>0,1,0)+IF(E10>0,1,0) | I10: =COUNTIF('03_통합데이터'!$J$3:$J$1002,$B10) | J10: =IF(H10>=3,"◎ 3개팀 중복",IF(H10=2,"○ 2개팀 중복",IF(H10=1,"단독 수행","미기록"))) | K10: =IF(H10>=2,ROUND(H10*G10,1),0)
A11: 상품기획·소싱 | B11: PLN-05 샘플 요청·검토 | C11: =SUMIFS('03_통합데이터'!$H$3:$H$1002,'03_통합데이터'!$J$3:$J$1002,$B11,'03_통합데이터'!$A$3:$A$1002,"미디어커머스") | D11: =SUMIFS('03_통합데이터'!$H$3:$H$1002,'03_통합데이터'!$J$3:$J$1002,$B11,'03_통합데이터'!$A$3:$A$1002,"브랜드커머스") | E11: =SUMIFS('03_통합데이터'!$H$3:$H$1002,'03_통합데이터'!$J$3:$J$1002,$B11,'03_통합데이터'!$A$3:$A$1002,"해외제조") | F11: =SUM(C11:E11) | G11: =ROUND(F11/60,1) | H11: =IF(C11>0,1,0)+IF(D11>0,1,0)+IF(E11>0,1,0) | I11: =COUNTIF('03_통합데이터'!$J$3:$J$1002,$B11) | J11: =IF(H11>=3,"◎ 3개팀 중복",IF(H11=2,"○ 2개팀 중복",IF(H11=1,"단독 수행","미기록"))) | K11: =IF(H11>=2,ROUND(H11*G11,1),0)
A12: 상품기획·소싱 | B12: PLN-06 상품 스펙·사양 확정 | C12: =SUMIFS('03_통합데이터'!$H$3:$H$1002,'03_통합데이터'!$J$3:$J$1002,$B12,'03_통합데이터'!$A$3:$A$1002,"미디어커머스") | D12: =SUMIFS('03_통합데이터'!$H$3:$H$1002,'03_통합데이터'!$J$3:$J$1002,$B12,'03_통합데이터'!$A$3:$A$1002,"브랜드커머스") | E12: =SUMIFS('03_통합데이터'!$H$3:$H$1002,'03_통합데이터'!$J$3:$J$1002,$B12,'03_통합데이터'!$A$3:$A$1002,"해외제조") | F12: =SUM(C12:E12) | G12: =ROUND(F12/60,1) | H12: =IF(C12>0,1,0)+IF(D12>0,1,0)+IF(E12>0,1,0) | I12: =COUNTIF('03_통합데이터'!$J$3:$J$1002,$B12) | J12: =IF(H12>=3,"◎ 3개팀 중복",IF(H12=2,"○ 2개팀 중복",IF(H12=1,"단독 수행","미기록"))) | K12: =IF(H12>=2,ROUND(H12*G12,1),0)
A13: 제조·생산관리 | B13: MFG-01 해외공장/거래처 커뮤니케이션 | C13: =SUMIFS('03_통합데이터'!$H$3:$H$1002,'03_통합데이터'!$J$3:$J$1002,$B13,'03_통합데이터'!$A$3:$A$1002,"미디어커머스") | D13: =SUMIFS('03_통합데이터'!$H$3:$H$1002,'03_통합데이터'!$J$3:$J$1002,$B13,'03_통합데이터'!$A$3:$A$1002,"브랜드커머스") | E13: =SUMIFS('03_통합데이터'!$H$3:$H$1002,'03_통합데이터'!$J$3:$J$1002,$B13,'03_통합데이터'!$A$3:$A$1002,"해외제조") | F13: =SUM(C13:E13) | G13: =ROUND(F13/60,1) | H13: =IF(C13>0,1,0)+IF(D13>0,1,0)+IF(E13>0,1,0) | I13: =COUNTIF('03_통합데이터'!$J$3:$J$1002,$B13) | J13: =IF(H13>=3,"◎ 3개팀 중복",IF(H13=2,"○ 2개팀 중복",IF(H13=1,"단독 수행","미기록"))) | K13: =IF(H13>=2,ROUND(H13*G13,1),0)
A14: 제조·생산관리 | B14: MFG-02 발주(PO) 작성·전송 | C14: =SUMIFS('03_통합데이터'!$H$3:$H$1002,'03_통합데이터'!$J$3:$J$1002,$B14,'03_통합데이터'!$A$3:$A$1002,"미디어커머스") | D14: =SUMIFS('03_통합데이터'!$H$3:$H$1002,'03_통합데이터'!$J$3:$J$1002,$B14,'03_통합데이터'!$A$3:$A$1002,"브랜드커머스") | E14: =SUMIFS('03_통합데이터'!$H$3:$H$1002,'03_통합데이터'!$J$3:$J$1002,$B14,'03_통합데이터'!$A$3:$A$1002,"해외제조") | F14: =SUM(C14:E14) | G14: =ROUND(F14/60,1) | H14: =IF(C14>0,1,0)+IF(D14>0,1,0)+IF(E14>0,1,0) | I14: =COUNTIF('03_통합데이터'!$J$3:$J$1002,$B14) | J14: =IF(H14>=3,"◎ 3개팀 중복",IF(H14=2,"○ 2개팀 중복",IF(H14=1,"단독 수행","미기록"))) | K14: =IF(H14>=2,ROUND(H14*G14,1),0)
A15: 제조·생산관리 | B15: MFG-03 생산일정 관리·납기 독촉 | C15: =SUMIFS('03_통합데이터'!$H$3:$H$1002,'03_통합데이터'!$J$3:$J$1002,$B15,'03_통합데이터'!$A$3:$A$1002,"미디어커머스") | D15: =SUMIFS('03_통합데이터'!$H$3:$H$1002,'03_통합데이터'!$J$3:$J$1002,$B15,'03_통합데이터'!$A$3:$A$1002,"브랜드커머스") | E15: =SUMIFS('03_통합데이터'!$H$3:$H$1002,'03_통합데이터'!$J$3:$J$1002,$B15,'03_통합데이터'!$A$3:$A$1002,"해외제조") | F15: =SUM(C15:E15) | G15: =ROUND(F15/60,1) | H15: =IF(C15>0,1,0)+IF(D15>0,1,0)+IF(E15>0,1,0) | I15: =COUNTIF('03_통합데이터'!$J$3:$J$1002,$B15) | J15: =IF(H15>=3,"◎ 3개팀 중복",IF(H15=2,"○ 2개팀 중복",IF(H15=1,"단독 수행","미기록"))) | K15: =IF(H15>=2,ROUND(H15*G15,1),0)
A16: 제조·생산관리 | B16: MFG-04 품질검사(QC)·불량 대응 | C16: =SUMIFS('03_통합데이터'!$H$3:$H$1002,'03_통합데이터'!$J$3:$J$1002,$B16,'03_통합데이터'!$A$3:$A$1002,"미디어커머스") | D16: =SUMIFS('03_통합데이터'!$H$3:$H$1002,'03_통합데이터'!$J$3:$J$1002,$B16,'03_통합데이터'!$A$3:$A$1002,"브랜드커머스") | E16: =SUMIFS('03_통합데이터'!$H$3:$H$1002,'03_통합데이터'!$J$3:$J$1002,$B16,'03_통합데이터'!$A$3:$A$1002,"해외제조") | F16: =SUM(C16:E16) | G16: =ROUND(F16/60,1) | H16: =IF(C16>0,1,0)+IF(D16>0,1,0)+IF(E16>0,1,0) | I16: =COUNTIF('03_통합데이터'!$J$3:$J$1002,$B16) | J16: =IF(H16>=3,"◎ 3개팀 중복",IF(H16=2,"○ 2개팀 중복",IF(H16=1,"단독 수행","미기록"))) | K16: =IF(H16>=2,ROUND(H16*G16,1),0)
A17: 제조·생산관리 | B17: MFG-05 수입통관·인증(KC 등) 처리 | C17: =SUMIFS('03_통합데이터'!$H$3:$H$1002,'03_통합데이터'!$J$3:$J$1002,$B17,'03_통합데이터'!$A$3:$A$1002,"미디어커머스") | D17: =SUMIFS('03_통합데이터'!$H$3:$H$1002,'03_통합데이터'!$J$3:$J$1002,$B17,'03_통합데이터'!$A$3:$A$1002,"브랜드커머스") | E17: =SUMIFS('03_통합데이터'!$H$3:$H$1002,'03_통합데이터'!$J$3:$J$1002,$B17,'03_통합데이터'!$A$3:$A$1002,"해외제조") | F17: =SUM(C17:E17) | G17: =ROUND(F17/60,1) | H17: =IF(C17>0,1,0)+IF(D17>0,1,0)+IF(E17>0,1,0) | I17: =COUNTIF('03_통합데이터'!$J$3:$J$1002,$B17) | J17: =IF(H17>=3,"◎ 3개팀 중복",IF(H17=2,"○ 2개팀 중복",IF(H17=1,"단독 수행","미기록"))) | K17: =IF(H17>=2,ROUND(H17*G17,1),0)
A18: 제조·생산관리 | B18: MFG-06 선적·입고 일정 관리 | C18: =SUMIFS('03_통합데이터'!$H$3:$H$1002,'03_통합데이터'!$J$3:$J$1002,$B18,'03_통합데이터'!$A$3:$A$1002,"미디어커머스") | D18: =SUMIFS('03_통합데이터'!$H$3:$H$1002,'03_통합데이터'!$J$3:$J$1002,$B18,'03_통합데이터'!$A$3:$A$1002,"브랜드커머스") | E18: =SUMIFS('03_통합데이터'!$H$3:$H$1002,'03_통합데이터'!$J$3:$J$1002,$B18,'03_통합데이터'!$A$3:$A$1002,"해외제조") | F18: =SUM(C18:E18) | G18: =ROUND(F18/60,1) | H18: =IF(C18>0,1,0)+IF(D18>0,1,0)+IF(E18>0,1,0) | I18: =COUNTIF('03_통합데이터'!$J$3:$J$1002,$B18) | J18: =IF(H18>=3,"◎ 3개팀 중복",IF(H18=2,"○ 2개팀 중복",IF(H18=1,"단독 수행","미기록"))) | K18: =IF(H18>=2,ROUND(H18*G18,1),0)
... A67: 기타·행정 | B67: ETC-05 휴게·점심 | C67: =SUMIFS('03_통합데이터'!$H$3:$H$1002,'03_통합데이터'!$J$3:$J$1002,$B67,'03_통합데이터'!$A$3:$A$1002,"미디어커머스") | D67: =SUMIFS('03_통합데이터'!$H$3:$H$1002,'03_통합데이터'!$J$3:$J$1002,$B67,'03_통합데이터'!$A$3:$A$1002,"브랜드커머스") | E67: =SUMIFS('03_통합데이터'!$H$3:$H$1002,'03_통합데이터'!$J$3:$J$1002,$B67,'03_통합데이터'!$A$3:$A$1002,"해외제조") | F67: =SUM(C67:E67) | G67: =ROUND(F67/60,1) | H67: =IF(C67>0,1,0)+IF(D67>0,1,0)+IF(E67>0,1,0) | I67: =COUNTIF('03_통합데이터'!$J$3:$J$1002,$B67) | J67: =IF(H67>=3,"◎ 3개팀 중복",IF(H67=2,"○ 2개팀 중복",IF(H67=1,"단독 수행","미기록"))) | K67: =IF(H67>=2,ROUND(H67*G67,1),0)
A70: ▣ 업무 대분류별 팀 투입 비교 (어느 영역이 겹치는지 한눈에)
A71: 업무 대분류 | B71: 미디어커머스(h) | C71: 브랜드커머스(h) | D71: 해외제조(h) | E71: 합계(h) | F71: 수행 팀수 | G71: 판정
A72: 상품기획·소싱 | B72: =ROUND(SUMIFS('03_통합데이터'!$H$3:$H$1002,'03_통합데이터'!$I$3:$I$1002,$A72,'03_통합데이터'!$A$3:$A$1002,"미디어커머스")/60,1) | C72: =ROUND(SUMIFS('03_통합데이터'!$H$3:$H$1002,'03_통합데이터'!$I$3:$I$1002,$A72,'03_통합데이터'!$A$3:$A$1002,"브랜드커머스")/60,1) | D72: =ROUND(SUMIFS('03_통합데이터'!$H$3:$H$1002,'03_통합데이터'!$I$3:$I$1002,$A72,'03_통합데이터'!$A$3:$A$1002,"해외제조")/60,1) | E72: =ROUND(SUM(B72:D72),1) | F72: =IF(B72>0,1,0)+IF(C72>0,1,0)+IF(D72>0,1,0) | G72: =IF(F72>=3,"◎ 전팀 수행",IF(F72=2,"○ 2개팀",""))
A73: 제조·생산관리 | B73: =ROUND(SUMIFS('03_통합데이터'!$H$3:$H$1002,'03_통합데이터'!$I$3:$I$1002,$A73,'03_통합데이터'!$A$3:$A$1002,"미디어커머스")/60,1) | C73: =ROUND(SUMIFS('03_통합데이터'!$H$3:$H$1002,'03_통합데이터'!$I$3:$I$1002,$A73,'03_통합데이터'!$A$3:$A$1002,"브랜드커머스")/60,1) | D73: =ROUND(SUMIFS('03_통합데이터'!$H$3:$H$1002,'03_통합데이터'!$I$3:$I$1002,$A73,'03_통합데이터'!$A$3:$A$1002,"해외제조")/60,1) | E73: =ROUND(SUM(B73:D73),1) | F73: =IF(B73>0,1,0)+IF(C73>0,1,0)+IF(D73>0,1,0) | G73: =IF(F73>=3,"◎ 전팀 수행",IF(F73=2,"○ 2개팀",""))
A74: 마케팅·광고운영 | B74: =ROUND(SUMIFS('03_통합데이터'!$H$3:$H$1002,'03_통합데이터'!$I$3:$I$1002,$A74,'03_통합데이터'!$A$3:$A$1002,"미디어커머스")/60,1) | C74: =ROUND(SUMIFS('03_통합데이터'!$H$3:$H$1002,'03_통합데이터'!$I$3:$I$1002,$A74,'03_통합데이터'!$A$3:$A$1002,"브랜드커머스")/60,1) | D74: =ROUND(SUMIFS('03_통합데이터'!$H$3:$H$1002,'03_통합데이터'!$I$3:$I$1002,$A74,'03_통합데이터'!$A$3:$A$1002,"해외제조")/60,1) | E74: =ROUND(SUM(B74:D74),1) | F74: =IF(B74>0,1,0)+IF(C74>0,1,0)+IF(D74>0,1,0) | G74: =IF(F74>=3,"◎ 전팀 수행",IF(F74=2,"○ 2개팀",""))
A75: 콘텐츠제작 | B75: =ROUND(SUMIFS('03_통합데이터'!$H$3:$H$1002,'03_통합데이터'!$I$3:$I$1002,$A75,'03_통합데이터'!$A$3:$A$1002,"미디어커머스")/60,1) | C75: =ROUND(SUMIFS('03_통합데이터'!$H$3:$H$1002,'03_통합데이터'!$I$3:$I$1002,$A75,'03_통합데이터'!$A$3:$A$1002,"브랜드커머스")/60,1) | D75: =ROUND(SUMIFS('03_통합데이터'!$H$3:$H$1002,'03_통합데이터'!$I$3:$I$1002,$A75,'03_통합데이터'!$A$3:$A$1002,"해외제조")/60,1) | E75: =ROUND(SUM(B75:D75),1) | F75: =IF(B75>0,1,0)+IF(C75>0,1,0)+IF(D75>0,1,0) | G75: =IF(F75>=3,"◎ 전팀 수행",IF(F75=2,"○ 2개팀",""))
A76: 채널·스토어운영 | B76: =ROUND(SUMIFS('03_통합데이터'!$H$3:$H$1002,'03_통합데이터'!$I$3:$I$1002,$A76,'03_통합데이터'!$A$3:$A$1002,"미디어커머스")/60,1) | C76: =ROUND(SUMIFS('03_통합데이터'!$H$3:$H$1002,'03_통합데이터'!$I$3:$I$1002,$A76,'03_통합데이터'!$A$3:$A$1002,"브랜드커머스")/60,1) | D76: =ROUND(SUMIFS('03_통합데이터'!$H$3:$H$1002,'03_통합데이터'!$I$3:$I$1002,$A76,'03_통합데이터'!$A$3:$A$1002,"해외제조")/60,1) | E76: =ROUND(SUM(B76:D76),1) | F76: =IF(B76>0,1,0)+IF(C76>0,1,0)+IF(D76>0,1,0) | G76: =IF(F76>=3,"◎ 전팀 수행",IF(F76=2,"○ 2개팀",""))
A77: CS·물류·재고 | B77: =ROUND(SUMIFS('03_통합데이터'!$H$3:$H$1002,'03_통합데이터'!$I$3:$I$1002,$A77,'03_통합데이터'!$A$3:$A$1002,"미디어커머스")/60,1) | C77: =ROUND(SUMIFS('03_통합데이터'!$H$3:$H$1002,'03_통합데이터'!$I$3:$I$1002,$A77,'03_통합데이터'!$A$3:$A$1002,"브랜드커머스")/60,1) | D77: =ROUND(SUMIFS('03_통합데이터'!$H$3:$H$1002,'03_통합데이터'!$I$3:$I$1002,$A77,'03_통합데이터'!$A$3:$A$1002,"해외제조")/60,1) | E77: =ROUND(SUM(B77:D77),1) | F77: =IF(B77>0,1,0)+IF(C77>0,1,0)+IF(D77>0,1,0) | G77: =IF(F77>=3,"◎ 전팀 수행",IF(F77=2,"○ 2개팀",""))
A78: 데이터·정산 | B78: =ROUND(SUMIFS('03_통합데이터'!$H$3:$H$1002,'03_통합데이터'!$I$3:$I$1002,$A78,'03_통합데이터'!$A$3:$A$1002,"미디어커머스")/60,1) | C78: =ROUND(SUMIFS('03_통합데이터'!$H$3:$H$1002,'03_통합데이터'!$I$3:$I$1002,$A78,'03_통합데이터'!$A$3:$A$1002,"브랜드커머스")/60,1) | D78: =ROUND(SUMIFS('03_통합데이터'!$H$3:$H$1002,'03_통합데이터'!$I$3:$I$1002,$A78,'03_통합데이터'!$A$3:$A$1002,"해외제조")/60,1) | E78: =ROUND(SUM(B78:D78),1) | F78: =IF(B78>0,1,0)+IF(C78>0,1,0)+IF(D78>0,1,0) | G78: =IF(F78>=3,"◎ 전팀 수행",IF(F78=2,"○ 2개팀",""))
A79: 기획·보고·회의 | B79: =ROUND(SUMIFS('03_통합데이터'!$H$3:$H$1002,'03_통합데이터'!$I$3:$I$1002,$A79,'03_통합데이터'!$A$3:$A$1002,"미디어커머스")/60,1) | C79: =ROUND(SUMIFS('03_통합데이터'!$H$3:$H$1002,'03_통합데이터'!$I$3:$I$1002,$A79,'03_통합데이터'!$A$3:$A$1002,"브랜드커머스")/60,1) | D79: =ROUND(SUMIFS('03_통합데이터'!$H$3:$H$1002,'03_통합데이터'!$I$3:$I$1002,$A79,'03_통합데이터'!$A$3:$A$1002,"해외제조")/60,1) | E79: =ROUND(SUM(B79:D79),1) | F79: =IF(B79>0,1,0)+IF(C79>0,1,0)+IF(D79>0,1,0) | G79: =IF(F79>=3,"◎ 전팀 수행",IF(F79=2,"○ 2개팀",""))
A80: 사내시스템·자동화 | B80: =ROUND(SUMIFS('03_통합데이터'!$H$3:$H$1002,'03_통합데이터'!$I$3:$I$1002,$A80,'03_통합데이터'!$A$3:$A$1002,"미디어커머스")/60,1) | C80: =ROUND(SUMIFS('03_통합데이터'!$H$3:$H$1002,'03_통합데이터'!$I$3:$I$1002,$A80,'03_통합데이터'!$A$3:$A$1002,"브랜드커머스")/60,1) | D80: =ROUND(SUMIFS('03_통합데이터'!$H$3:$H$1002,'03_통합데이터'!$I$3:$I$1002,$A80,'03_통합데이터'!$A$3:$A$1002,"해외제조")/60,1) | E80: =ROUND(SUM(B80:D80),1) | F80: =IF(B80>0,1,0)+IF(C80>0,1,0)+IF(D80>0,1,0) | G80: =IF(F80>=3,"◎ 전팀 수행",IF(F80=2,"○ 2개팀",""))
A81: 파트너·대리점관리 | B81: =ROUND(SUMIFS('03_통합데이터'!$H$3:$H$1002,'03_통합데이터'!$I$3:$I$1002,$A81,'03_통합데이터'!$A$3:$A$1002,"미디어커머스")/60,1) | C81: =ROUND(SUMIFS('03_통합데이터'!$H$3:$H$1002,'03_통합데이터'!$I$3:$I$1002,$A81,'03_통합데이터'!$A$3:$A$1002,"브랜드커머스")/60,1) | D81: =ROUND(SUMIFS('03_통합데이터'!$H$3:$H$1002,'03_통합데이터'!$I$3:$I$1002,$A81,'03_통합데이터'!$A$3:$A$1002,"해외제조")/60,1) | E81: =ROUND(SUM(B81:D81),1) | F81: =IF(B81>0,1,0)+IF(C81>0,1,0)+IF(D81>0,1,0) | G81: =IF(F81>=3,"◎ 전팀 수행",IF(F81=2,"○ 2개팀",""))
A82: 기타·행정 | B82: =ROUND(SUMIFS('03_통합데이터'!$H$3:$H$1002,'03_통합데이터'!$I$3:$I$1002,$A82,'03_통합데이터'!$A$3:$A$1002,"미디어커머스")/60,1) | C82: =ROUND(SUMIFS('03_통합데이터'!$H$3:$H$1002,'03_통합데이터'!$I$3:$I$1002,$A82,'03_통합데이터'!$A$3:$A$1002,"브랜드커머스")/60,1) | D82: =ROUND(SUMIFS('03_통합데이터'!$H$3:$H$1002,'03_통합데이터'!$I$3:$I$1002,$A82,'03_통합데이터'!$A$3:$A$1002,"해외제조")/60,1) | E82: =ROUND(SUM(B82:D82),1) | F82: =IF(B82>0,1,0)+IF(C82>0,1,0)+IF(D82>0,1,0) | G82: =IF(F82>=3,"◎ 전팀 수행",IF(F82=2,"○ 2개팀",""))

Sheet 05_통합기회도출
A1: 통합 기회 도출 시트 — 04 분석에서 '중복' 판정된 업무를 옮겨 적고 통합안을 설계
A2: 작성 순서 ▶ ① 04시트를 '통합우선순위점수' 기준 내림차순 정렬 → ② 상위 항목을 아래로 옮겨 적기 → ③ 각 팀 담당자에게 '어떻게 하는지' 확인 후 수행방식 차이 기재 → ④ 통합 유형/주관 결정
A3: 연번 | B3: 중복 업무 (중분류) | C3: 관련 팀 | D3: 각 팀 현재 수행 방식 차이 | E3: 중복 발생 원인 | F3: 통합 방안 | G3: 통합 유형 | H3: 주관 조직(안) | I3: 월 예상 절감시간(h) | J3: 실행 난이도 | K3: 우선순위 | L3: 비고
A4: 1 | B4: MKT-02 광고 성과 모니터링·최적화 | C4: 미디어/브랜드/해외제조 | D4: 3팀 모두 매일 오전 각자 광고관리자 접속 → 각자 양식의 구글시트에 수기 집계 | E4: 성과 데이터 소스는 동일하나 집계 양식과 보고 라인이 팀별로 분리되어 있음 | F4: 본부 공용 광고 대시보드 1개 구축, 자동 수집. 팀은 '해석·조치'만 수행 | G4: 툴 공용화 + 자동화 | H4: 미디어커머스 | I4: 24 | J4: 중 | K4: 1순위 | L4: 대행사 계정 권한 통합 필요
A5: 2
A6: 3
A7: 4
A8: 5
A9: 6
A10: 7
A11: 8
A12: 9
A13: 10
A14: 11
A15: 12
A16: 13
... A39: 36
